Workbook

Sheet Rules
A1: RTO Permit | B1: Insu Permit
A2: Private - U/C (4 Wheeler) | B2: Private
A3: Private - U/C EV (4 Wheeler) | B3: Private
A4: Private - BH (4 Wheeler) | B4: Private
A5: Private - BH EV (4 Wheeler) | B5: Private
A6: Goods - G (4 Wheeler) | B6: Goods
A7: Goods - G EV (4 Wheeler) | B7: Goods
A8: Goods - G 3 Ton+ (4 Wheeler) | B8: Goods
A9: Goods - G 3 Ton+ EV (4 Wheeler) | B9: Goods
A10: Goods - G (3 Wheeler) | B10: Goods
A11: Goods - G EV (3 Wheeler) | B11: Goods
A12: Taxi - T (4 Wheeler) | B12: Passenger
... A16: Ambulance (Misc.) | B16: Misc

Sheet Vehicle Info
A1: Model Code | B1: OEM Model | C1: OEM Variant | D1: Segment | E1: Sub Segment | F1: Fuel | G1: Seating | H1: Wheels | I1: Transmission | J1: Drivetrain | K1: Body Make | L1: Body Type | M1: CC | N1: Motor | O1: GVW | P1: GST% | Q1: Permit | R1: Taxi Price | S1: Custom Model | T1: Custom Variant | U1: Display Name | V1: Colour Name | W1: Status | X1: Shield Pack
A2: 1AM2NW1T9MBB1BL | B2: ALFA LOAD DUO | C2: ALFA LC PLUS CNG DUO BSVI BLK | D2: LMM | E2: LMM | F2: CNG | G2: 4 | H2: 3 | I2: MANUAL | J2: RWD | K2: CARGO | L2: COMPLETE | O2: 995 | P2: 0.18 | Q2: GOODS | R2: NO | S2: ALFA LOAD DUO | T2: CNG DUO BSVI | U2: ALFA LOAD DUO CNG BS6 | V2: BLACK | W2: ACTIVE
A3: 1AM2NW1T9MBB1GY | B3: ALFA LOAD DUO | C3: ALFA LC PLUS CNG DUO BSVI GOLD YW | D3: LMM | E3: LMM | F3: CNG | G3: 4 | H3: 3 | I3: MANUAL | J3: RWD | K3: CARGO | L3: COMPLETE | O3: 995 | P3: 0.18 | Q3: GOODS | R3: NO | S3: ALFA LOAD DUO | T3: CNG DUO BSVI | U3: ALFA LOAD DUO CNG BS6 | V3: GOLDEN YELLOW | W3: ACTIVE
A4: 1AM2NW1T9MBB1NB | B4: ALFA LOAD DUO | C4: ALFA LC PLUS CNG DUO BSVI NISS BLU | D4: LMM | E4: LMM | F4: CNG | G4: 4 | H4: 3 | I4: MANUAL | J4: RWD | K4: CARGO | L4: COMPLETE | O4: 995 | P4: 0.18 | Q4: GOODS | R4: NO | S4: ALFA LOAD DUO | T4: CNG DUO BSVI | U4: ALFA LOAD DUO CNG BS6 | V4: NISSAN BLUE | W4: ACTIVE
A5: BH826H1ZH7U6RX | B5: Bolero | C5: B6 BS6.2 - Refresh | D5: PV | E5: NON XUV | F5: DIESEL | G5: 7 | H5: 4 | I5: MANUAL | J5: RWD | K5: SUV | L5: COMPLETE | M5: 1493 | P5: 0.18 | Q5: PRIVATE | R5: YES | S5: BOLERO | T5: B6 BS6.2 - REFRESH | U5: BOLERO B6 BS6.2 - REFRESH | V5: HIGHWAY RED | W5: ACTIVE
A6: BH826H1ZH7U6SK | B6: Bolero | C6: B6 BS6.2 - Refresh | D6: PV | E6: NON XUV | F6: DIESEL | G6: 7 | H6: 4 | I6: MANUAL | J6: RWD | K6: SUV | L6: COMPLETE | M6: 1493 | P6: 0.18 | Q6: PRIVATE | R6: YES | S6: BOLERO | T6: B6 BS6.2 - REFRESH | U6: BOLERO B6 BS6.2 - REFRESH | V6: DSAT SILVER | W6: ACTIVE
A7: BH826H1ZH7U6WD | B7: Bolero | C7: B6 BS6.2 - Refresh | D7: PV | E7: NON XUV | F7: DIESEL | G7: 7 | H7: 4 | I7: MANUAL | J7: RWD | K7: SUV | L7: COMPLETE | M7: 1493 | P7: 0.18 | Q7: PRIVATE | R7: YES | S7: BOLERO | T7: B6 BS6.2 - REFRESH | U7: BOLERO B6 BS6.2 - REFRESH | V7: WHITE | W7: ACTIVE
A8: PFN2FAMMBS6PPFD3WD | B8: MAXX CITY | C8: MAXX CITY 1.4 VXi AC - BS6.2 | D8: CV | E8: CV | F8: DIESEL | G8: 3 | H8: 4 | I8: MANUAL | J8: RWD | K8: CARGO | L8: COMPLETE | O8: 2995 | P8: 0.18 | Q8: GOODS | R8: NO | S8: MAXX CITY | T8: 1.4 VXI AC - BS6.2 | U8: MAXX CITY 1.4 VXI AC - BS6.2 | V8: DIAMOND WHITE | W8: ACTIVE
A9: PFN2FACEBS6PSFD3WD | B9: MAXX CITY | C9: MAXX CITY 1.5 LX BS6.2 | D9: CV | E9: CV | F9: DIESEL | G9: 3 | H9: 4 | I9: MANUAL | J9: RWD | K9: CARGO | L9: COMPLETE | O9: 3120 | P9: 0.18 | Q9: GOODS | R9: NO | S9: MAXX CITY | T9: 1.5 LX BS6.2 | U9: MAXX CITY 1.5 LX BS6.2 | V9: DIAMOND WHITE | W9: ACTIVE
A10: PFN2EABKBS6PSTG3WD | B10: MAXX HD | C10: MAXX HD 1.7 LX CBC BS6.2 - Tipper / Hopper | D10: CV | E10: CV | F10: DIESEL | G10: 3 | H10: 4 | I10: MANUAL | J10: RWD | K10: CARGO | L10: CBC | O10: 3460 | P10: 0.18 | Q10: GOODS | R10: NO | S10: MAXX HD | T10: 1.7 LX CBC BS6.2 - TIPPER / HOPPER | U10: MAXX HD 1.7 LX CBC BS6.2 - TIPPER / HOPPER | V10: WHITE | W10: ACTIVE
A11: PFN2EDDNBS6PPFD3WD | B11: MAXX HD | C11: MAXX HD 1.7 MXi BS6.2 | D11: CV | E11: CV | F11: DIESEL | G11: 3 | H11: 4 | I11: MANUAL | J11: RWD | K11: CARGO | L11: COMPLETE | O11: 3460 | P11: 0.18 | Q11: GOODS | R11: NO | S11: MAXX HD | T11: 1.7 MXI BS6.2 | U11: MAXX HD 1.7 MXI BS6.2 | V11: WHITE | W11: ACTIVE
A12: PFN2EADMBS6PPFD3WD | B12: MAXX HD | C12: MAXX HD 1.7 VXi AC - BS6.2 | D12: CV | E12: CV | F12: DIESEL | G12: 3 | H12: 4 | I12: MANUAL | J12: RWD | K12: CARGO | L12: COMPLETE | O12: 3460 | P12: 0.18 | Q12: GOODS | R12: NO | S12: MAXX HD | T12: 1.7 VXI AC - BS6.2 | U12: MAXX HD 1.7 VXI AC - BS6.2 | V12: WHITE | W12: ACTIVE
A13: PJN2EXCKBS6PSFD3WD | B13: MAXX HD | C13: MAXX HD 1.7L LX BS6.2 | D13: CV | E13: CV | F13: DIESEL | G13: 3 | H13: 4 | I13: MANUAL | J13: RWD | K13: CARGO | L13: COMPLETE | O13: 3460 | P13: 0.18 | Q13: GOODS | R13: NO | S13: MAXX HD | T13: 1.7L LX BS6.2 | U13: MAXX HD 1.7L LX BS6.2 | V13: WHITE | W13: ACTIVE
A14: PKN2ADCMBS6PSNC5CB | B14: PICKUP | C14: BOL CAMPER GOLD RXD BS6.2 - Refresh | D14: CV | E14: CV | F14: DIESEL | G14: 5 | H14: 4 | I14: MANUAL | J14: RWD | K14: CARGO | L14: COMPLETE | O14: 2735 | P14: 0.18 | Q14: GOODS | R14: NO | S14: CAMPER | T14: GOLD RXD BS6.2 - REFRESH | U14: CAMPER GOLD RXD BS6.2 - REFRESH | V14: JAVA BROWN | W14: ACTIVE
A15: PKN2ADCMBS6PSNC5WD | B15: PICKUP | C15: BOL CAMPER GOLD RXD BS6.2 - Refresh | D15: CV | E15: CV | F15: DIESEL | G15: 5 | H15: 4 | I15: MANUAL | J15: RWD | K15: CARGO | L15: COMPLETE | O15: 2735 | P15: 0.18 | Q15: GOODS | R15: NO | S15: CAMPER | T15: GOLD RXD BS6.2 - REFRESH | U15: CAMPER GOLD RXD BS6.2 - REFRESH | V15: WHITE | W15: ACTIVE
A16: PKN2ADC2BS6PSNC5WD | B16: PICKUP | C16: BOL CAMPER GOLD RXD BS6.2 CV - Refresh | D16: CV | E16: CV | F16: DIESEL | G16: 5 | H16: 4 | I16: MANUAL | J16: RWD | K16: CARGO | L16: COMPLETE | O16: 2735 | P16: 0.18 | Q16: GOODS | R16: NO | S16: CAMPER | T16: GOLD RXD BS6.2 CV - REFRESH | U16: CAMPER GOLD RXD BS6.2 CV - REFRESH | V16: WHITE | W16: ACTIVE
A17: SSS24MJA7R8E6WQ | B17: Scorpio | C17: Classic S11 BS6.2 - E | D17: PV | E17: NON XUV | F17: DIESEL | G17: 7 | H17: 4 | I17: MANUAL | J17: RWD | K17: SUV | L17: COMPLETE | M17: 2184 | P17: 0.4 | Q17: PRIVATE | R17: YES | S17: SCORPIO | T17: CLASSIC S11 BS6.2 - E | U17: SCORPIO CLASSIC S11 BS6.2 - E | V17: EVEREST WHITE | W17: ACTIVE
A18: SSS24MJA7R8E7QK | B18: Scorpio | C18: Classic S11 BS6.2 - E | D18: PV | E18: NON XUV | F18: DIESEL | G18: 7 | H18: 4 | I18: MANUAL | J18: RWD | K18: SUV | L18: COMPLETE | M18: 2184 | P18: 0.4 | Q18: PRIVATE | R18: YES | S18: SCORPIO | T18: CLASSIC S11 BS6.2 - E | U18: SCORPIO CLASSIC S11 BS6.2 - E | V18: GALAXY GREY | W18: ACTIVE
A19: SSS24MJA7R8E6QK | B19: Scorpio | C19: Classic S11 BS6.2 - E | D19: PV | E19: NON XUV | F19: DIESEL | G19: 7 | H19: 4 | I19: MANUAL | J19: RWD | K19: SUV | L19: COMPLETE | M19: 2184 | P19: 0.4 | Q19: PRIVATE | R19: YES | S19: SCORPIO | T19: CLASSIC S11 BS6.2 - E | U19: SCORPIO CLASSIC S11 BS6.2 - E | V19: GALAXY GREY | W19: ACTIVE
A20: SSS24MJA7R8E7WQ | B20: Scorpio | C20: Classic S11 BS6.2 - E | D20: PV | E20: NON XUV | F20: DIESEL | G20: 7 | H20: 4 | I20: MANUAL | J20: RWD | K20: SUV | L20: COMPLETE | M20: 2184 | P20: 0.4 | Q20: PRIVATE | R20: YES | S20: SCORPIO | T20: CLASSIC S11 BS6.2 - E | U20: SCORPIO CLASSIC S11 BS6.2 - E | V20: EVEREST WHITE | W20: ACTIVE
A21: AZ1116YJT2A4FA01WQ | B21: Scorpio-N | C21: Z2 D MT 2WD 7 STR - E BS6.2 - New | D21: PV | E21: NON XUV | F21: DIESEL | G21: 7 | H21: 4 | I21: MANUAL | J21: RWD | K21: SUV | L21: COMPLETE | M21: 2198 | P21: 0.4 | Q21: PRIVATE | R21: YES | S21: SCORPIO-N | T21: Z2 D MT 2WD 7 STR - E BS6.2 - NEW | U21: SCORPIO-N Z2 D MT 2WD 7 STR - E BS6.2 - NEW | V21: EVEREST WHITE | W21: ACTIVE
A22: AZ1116YJT2A4FA01XJ | B22: Scorpio-N | C22: Z2 D MT 2WD 7 STR - E BS6.2 - New | D22: PV | E22: NON XUV | F22: DIESEL | G22: 7 | H22: 4 | I22: MANUAL | J22: RWD | K22: SUV | L22: COMPLETE | M22: 2198 | P22: 0.4 | Q22: PRIVATE | R22: YES | S22: SCORPIO-N | T22: Z2 D MT 2WD 7 STR - E BS6.2 - NEW | U22: SCORPIO-N Z2 D MT 2WD 7 STR - E BS6.2 - NEW | V22: STEALTH BLACK | W22: ACTIVE
A23: AZ1116YJT2A4FA01SG | B23: Scorpio-N | C23: Z2 D MT 2WD 7 STR - E BS6.2 - New | D23: PV | E23: NON XUV | F23: DIESEL | G23: 7 | H23: 4 | I23: MANUAL | J23: RWD | K23: SUV | L23: COMPLETE | M23: 2198 | P23: 0.4 | Q23: PRIVATE | R23: YES | S23: SCORPIO-N | T23: Z2 D MT 2WD 7 STR - E BS6.2 - NEW | U23: SCORPIO-N Z2 D MT 2WD 7 STR - E BS6.2 - NEW | V23: VALARIAN SILVER | W23: ACTIVE
A24: AW5068ZAT2B1UC01QL | B24: Thar | C24: LXT P MT 4WD 4S HT BS6.2 | D24: PV | E24: NON XUV | F24: PETROL | G24: 4 | H24: 4 | I24: MANUAL | J24: 4WD | K24: SUV | L24: COMPLETE | M24: 1997 | P24: 0.4 | Q24: PRIVATE | R24: YES | S24: THAR | T24: LXT P MT 4WD 4S HT BS6.2 | U24: THAR LXT P MT 4WD 4S HT BS6.2 | V24: BATTLESHIP GREY | W24: ACTIVE
A25: AW5068ZAT2B1UC01RQ | B25: Thar | C25: LXT P MT 4WD 4S HT BS6.2 | D25: PV | E25: NON XUV | F25: PETROL | G25: 4 | H25: 4 | I25: MANUAL | J25: 4WD | K25: SUV | L25: COMPLETE | M25: 1997 | P25: 0.4 | Q25: PRIVATE | R25: YES | S25: THAR | T25: LXT P MT 4WD 4S HT BS6.2 | U25: THAR LXT P MT 4WD 4S HT BS6.2 | V25: TANGO RED | W25: ACTIVE
A26: AW5068ZAT2B1UC01WQ | B26: Thar | C26: LXT P MT 4WD 4S HT BS6.2 | D26: PV | E26: NON XUV | F26: PETROL | G26: 4 | H26: 4 | I26: MANUAL | J26: 4WD | K26: SUV | L26: COMPLETE | M26: 1997 | P26: 0.4 | Q26: PRIVATE | R26: YES | S26: THAR | T26: LXT P MT 4WD 4S HT BS6.2 | U26: THAR LXT P MT 4WD 4S HT BS6.2 | V26: EVEREST WHITE | W26: ACTIVE
A27: AW5068ZAT2B1UC01XJ | B27: Thar | C27: LXT P MT 4WD 4S HT BS6.2 | D27: PV | E27: NON XUV | F27: PETROL | G27: 4 | H27: 4 | I27: MANUAL | J27: 4WD | K27: SUV | L27: COMPLETE | M27: 1997 | P27: 0.4 | Q27: PRIVATE | R27: YES | S27: THAR | T27: LXT P MT 4WD 4S HT BS6.2 | U27: THAR LXT P MT 4WD 4S HT BS6.2 | V27: STEALTH BLACK | W27: ACTIVE
A28: AW5076YYT2D4MF01AH | B28: Thar Roxx | C28: AX3L DMT 2WD | D28: PV | E28: NON XUV | F28: DIESEL | G28: 5 | H28: 4 | I28: MANUAL | J28: RWD | K28: SUV | L28: COMPLETE | M28: 2184 | P28: 0.4 | Q28: PRIVATE | R28: YES | S28: THAR ROXX | T28: AX3L DMT 2WD | U28: THAR ROXX AX3L DMT 2WD | V28: DEEP FOREST | W28: ACTIVE
A29: AW5076YYT2D4MF01AJ | B29: Thar Roxx | C29: AX3L DMT 2WD | D29: PV | E29: NON XUV | F29: DIESEL | G29: 5 | H29: 4 | I29: MANUAL | J29: RWD | K29: SUV | L29: COMPLETE | M29: 2184 | P29: 0.4 | Q29: PRIVATE | R29: YES | S29: THAR ROXX | T29: AX3L DMT 2WD | U29: THAR ROXX AX3L DMT 2WD | V29: BURNT SIENNA | W29: ACTIVE
A30: 0000AMJ00390N | B30: TREO AUTO | C30: TREO 2.0 SFT OCEANIC BLUE | D30: LMM | E30: LMM | F30: ELECTRIC | G30: 4 | H30: 3 | I30: AUTOMATIC | J30: RWD | K30: PASSENGER | L30: COMPLETE | P30: 0.05 | Q30: PASSENGER | R30: NO | S30: TREO AUTO | T30: 2.0 SOFT TOP | U30: TREO AUTO 2.0 SOFT TOP | V30: OCEANIC BLUE | W30: ACTIVE
A31: 0000AMJ00650N | B31: TREO AUTO | C31: TREO 2.0 SFT ROSE PINK | D31: LMM | E31: LMM | F31: ELECTRIC | G31: 4 | H31: 3 | I31: AUTOMATIC | J31: RWD | K31: PASSENGER | L31: COMPLETE | P31: 0.05 | Q31: PASSENGER | R31: NO | S31: TREO AUTO | T31: 2.0 SOFT TOP | U31: TREO AUTO 2.0 SOFT TOP | V31: ROSE PINK | W31: ACTIVE
A32: 0000ATA00030N | B32: TREO PLUS SM | C32: TREO PLUS SFT SM BLK YEL | D32: LMM | E32: LMM | F32: ELECTRIC | G32: 4 | H32: 3 | I32: AUTOMATIC | J32: RWD | K32: PASSENGER | L32: COMPLETE | P32: 0.05 | Q32: PASSENGER | R32: NO | S32: TREO PLUS METAL | T32: SOFT TOP | U32: TREO PLUS METAL SOFT TOP | V32: BLACK YELLOW | W32: ACTIVE
A33: 0000ATA00030N | B33: TREO PLUS SM | C33: TREO PLUS SFT SM BLK YEL | D33: LMM | E33: LMM | F33: ELECTRIC | G33: 4 | H33: 3 | I33: AUTOMATIC | J33: RWD | K33: PASSENGER | L33: COMPLETE | P33: 0.05 | Q33: PASSENGER | R33: NO | S33: TREO PLUS METAL | T33: SOFT TOP | U33: TREO PLUS METAL SOFT TOP | V33: BLACK YELLOW | W33: ACTIVE
A34: 0000ATA00250N | B34: TREO PLUS SM | C34: TREO PLUS SFT SM BLK-OCEANIC BLUE | D34: LMM | E34: LMM | F34: ELECTRIC | G34: 4 | H34: 3 | I34: AUTOMATIC | J34: RWD | K34: PASSENGER | L34: COMPLETE | P34: 0.05 | Q34: PASSENGER | R34: NO | S34: TREO PLUS METAL | T34: SOFT TOP | U34: TREO PLUS METAL SOFT TOP | V34: OCEANIC BLUE | W34: ACTIVE
A35: 0000ATA00250N | B35: TREO PLUS SM | C35: TREO PLUS SFT SM BLK-OCEANIC BLUE | D35: LMM | E35: LMM | F35: ELECTRIC | G35: 4 | H35: 3 | I35: AUTOMATIC | J35: RWD | K35: PASSENGER | L35: COMPLETE | P35: 0.05 | Q35: PASSENGER | R35: NO | S35: TREO PLUS METAL | T35: SOFT TOP | U35: TREO PLUS METAL SOFT TOP | V35: OCEANIC BLUE | W35: ACTIVE
A36: 0000ATA00220N | B36: TREO PLUS SM | C36: TREO PLUS SFT SM GREEN -YEL | D36: LMM | E36: LMM | F36: ELECTRIC | G36: 4 | H36: 3 | I36: AUTOMATIC | J36: RWD | K36: PASSENGER | L36: COMPLETE | P36: 0.05 | Q36: PASSENGER | R36: NO | S36: TREO PLUS METAL | T36: SOFT TOP | U36: TREO PLUS METAL SOFT TOP | V36: GREEN YELLOW | W36: ACTIVE
A37: 0000ATA00220N | B37: TREO PLUS SM | C37: TREO PLUS SFT SM GREEN -YEL | D37: LMM | E37: LMM | F37: ELECTRIC | G37: 4 | H37: 3 | I37: AUTOMATIC | J37: RWD | K37: PASSENGER | L37: COMPLETE | P37: 0.05 | Q37: PASSENGER | R37: NO | S37: TREO PLUS METAL | T37: SOFT TOP | U37: TREO PLUS METAL SOFT TOP | V37: GREEN YELLOW | W37: ACTIVE
A38: 0000ATA00210N | B38: TREO PLUS SM | C38: TREO PLUS SFT SM-DEMO | D38: LMM | E38: LMM | F38: ELECTRIC | G38: 4 | H38: 3 | I38: AUTOMATIC | J38: RWD | K38: PASSENGER | L38: COMPLETE | P38: 0.05 | Q38: PASSENGER | R38: NO | S38: TREO PLUS METAL | T38: SOFT TOP-DEMO | U38: TREO PLUS METAL SOFT TOP-DEMO | V38: BLUE WHITE | W38: INACTIVE
A39: 0000ATA00180N | B39: TREO SM | C39: TREO HRT SM | D39: LMM | E39: LMM | F39: ELECTRIC | G39: 4 | H39: 3 | I39: AUTOMATIC | J39: RWD | K39: PASSENGER | L39: COMPLETE | P39: 0.05 | Q39: PASSENGER | R39: NO | S39: TREO METAL | T39: HARD TOP | U39: TREO METAL HARD TOP | V39: BLUE WHITE | W39: ACTIVE
A40: 0000ATA00180N | B40: TREO SM | C40: TREO HRT SM | D40: LMM | E40: LMM | F40: ELECTRIC | G40: 4 | H40: 3 | I40: AUTOMATIC | J40: RWD | K40: PASSENGER | L40: COMPLETE | P40: 0.05 | Q40: PASSENGER | R40: NO | S40: TREO METAL | T40: HARD TOP | U40: TREO METAL HARD TOP | V40: BLUE WHITE | W40: ACTIVE
...

Sheet PV Vehicle
A1: Model Code | B1: OEM Model | C1: OEM Variant | D1: Colour Name | E1: Transmission | F1: Seating | G1: Status
A2: SSS24MJA7R8E7XJ | B2: Scorpio | C2: Classic S11 BS6.2 - E | D2: STEALTH BLACK | E2: MT | F2: 7 | G2: Live
A3: SSS24MJA7R8E6XJ | B3: Scorpio | C3: Classic S11 BS6.2 - E | D3: STEALTH BLACK | E3: MT | F3: 7 | G3: Live
A4: AW5026JWT7D4KF01AL | B4: Thar Roxx | C4: AX7 PAT 2WD - Star Edition | D4: TANGO RED | E4: AT | F4: 5 | G4: Live
A5: AW5026JWT7D4KF01AM | B5: Thar Roxx | C5: AX7 PAT 2WD - Star Edition | D5: STEALTH BLACK | E5: AT | F5: 5 | G5: Live
A6: AW5026JWT7D4KF01AV | B6: Thar Roxx | C6: AX7 PAT 2WD - Star Edition | D6: CITRINE YELLOW | E6: AT | F6: 5 | G6: Live
A7: AW5026JWT7D4KF01ZP | B7: Thar Roxx | C7: AX7 PAT 2WD - Star Edition | D7: EVEREST WHITE | E7: AT | F7: 5 | G7: Live
A8: AW5026KYT7D4KF01AL | B8: Thar Roxx | C8: AX7 DAT 2WD - Star Edition | D8: TANGO RED | E8: AT | F8: 5 | G8: Live
A9: AW5026KYT7D4KF01AM | B9: Thar Roxx | C9: AX7 DAT 2WD - Star Edition | D9: STEALTH BLACK | E9: AT | F9: 5 | G9: Live
A10: AS22SB215MB08A00CE | B10: XUV400 | C10: EL PRO FC - Battery 39.4 Kwh - Charger 7.2 Kw - E | D10: ARCTIC BLUE | E10: AT | F10: 5 | G10: Live
A11: AS22SB215MB08A00QK | B11: XUV400 | C11: EL PRO FC - Battery 39.4 Kwh - Charger 7.2 Kw - E | D11: GALAXY GREY | E11: AT | F11: 5 | G11: Live
A12: AS22SB215MB08A00RP | B12: XUV400 | C12: EL PRO FC - Battery 39.4 Kwh - Charger 7.2 Kw - E | D12: NEBULA BLUE | E12: AT | F12: 5 | G12: Live
A13: AS22SB215MB08A00WQ | B13: XUV400 | C13: EL PRO FC - Battery 39.4 Kwh - Charger 7.2 Kw - E | D13: EVEREST WHITE | E13: AT | F13: 5 | G13: Live
... A243: AW5076KYT7D4PE01XJ | B243: Thar Roxx | C243: AX7L DAT 2WD - Mocha Interiors | D243: STEALTH BLACK | E243: AT | F243: 5 | G243: Live

Sheet CV Vehicle
A1: Model Code | B1: OEM Model | C1: OEM Variant | D1: Colour Name | E1: Seating | F1: Status
A2: PKN2ADCVBS6PSND5BP | B2: PICKUP | C2: BOL CAMPER 2WD POWER STEERING BS6.2 - CV | D2: WHITE | E2: 5 | F2: Live
A3: G2C4AACVXB3F1A01QT | B3: VEERO | C3: 1.5XXL SD V2 | D3: CONCRETE GREY | E3: 3 | F3: Live
A4: G2C4AACVXB3F1A01WT | B4: VEERO | C4: 1.5XXL SD V2 | D4: POLAR WHITE | E4: 3 | F4: Live
A5: PKN2ADC2BS6PSNC5WD | B5: PICKUP | C5: BOL CAMPER GOLD RXD BS6.2 CV - Refresh | D5: WHITE | E5: 5 | F5: Live
A6: PKN2ADCVBS6PSNC5WD | B6: PICKUP | C6: BOL CAMPER 2WD BS6.2 - CV - Refresh | D6: WHITE | E6: 5 | F6: Live
A7: AAR2KSPX2TW0GWD | B7: SUPRO | C7: Supro Minitruck Excel CNG DUO BS6.2 - Tipper / Hopper | D7: DIAMOND WHITE | E7: 2 | F7: Live
A8: PKN2ADCWBS6PSND5RX | B8: PICKUP | C8: BOL CAMPER GOLD ZX 2WD BS6.2 - NEW | D8: HIGHWAY RED | E8: 5 | F8: Live
A9: PJN2CSCJBS6MSCC2WD | B9: PICKUP | C9: BOL PIK UP CBC 1.3T - BS6.2 - MS - Refresh | D9: WHITE | E9: 2 | F9: Live
A10: PJN2CSCJBS6MSFC2WD | B10: PICKUP | C10: BOL PIK UP FB 1.3T - BS6.2 - MS -Refresh | D10: WHITE | E10: 2 | F10: Live
A11: PJN2CSCJBS6PSFC2WD | B11: PICKUP | C11: BOL PIK UP FB 1.3T - BS6.2 - PS - Refresh | D11: WHITE | E11: 2 | F11: Live
A12: PJN2CSCMBS6PSFC2WD | B12: PICKUP | C12: BOL PIK UP FB 1.3T - BS6.2 - PS AC - Refresh | D12: WHITE | E12: 2 | F12: Live
A13: PJN4ASCMBS6PSNC2WD | B13: PICKUP | C13: BOL PIK UP 4WD BS6.2 - PS AC - Refresh | D13: WHITE | E13: 2 | F13: Live
... A155: PKN4ASCNBS6PSNC2WD | B155: PICKUP | C155: BOL PIK UP 4WD BS6.2 - PS - Refresh | D155: WHITE | E155: 3 | F155: Live

Sheet Price List PV
L1: Current VIN | W1: Old VIN
A2: Model Code | B2: OEM Model | C2: OEM Variant | D2: Asse Value with Freight | E2: GST | F2: GST Amount | G2: MM Inv Amt | H2: Dealer Margin | I2: Dealer Handling | J2: GST Amount 1 | K2: Ex-Showroom Price ORG | L2: OEM Scheme @ BNDP | M2: OEM Scheme with GST | N2: Dealer Cont @ BNDP | O2: Dealer Contribution with GST | P2: Total Consumer Scheme with GST (OEM + Dealer) | Q2: Cash Discount | R2: Accessories Discount | S2: Shield Discount | T2: Check | U2: Acc Dsc Elg | V2: Sheld Disc Elg | W2: OEM Scheme @ BNDP | X2: OEM Scheme with GST | Y2: Dealer Cont @ BNDP | Z2: Dealer Contribution with GST | AA2: Total Consumer Scheme with GST (OEM + Dealer) | AB2: Cash Discount | AC2: Accessories Discount | AD2: Shield Discount | AE2: Check | AF2: Acc Dsc Elg | AG2: Sheld Disc Elg
A3: AZ1116YGTTA4EA01BZ | B3: Scorpio-N | C3: Z8 L D AT 2WD 7 STR BS6.2 - N - ADAS | D3: 1557827 | E3: 40 | F3: 623131 | G3: 2180958 | H3: 68245 | I3: 0 | J3: 27298 | K3: 2276500 | L3: 53571 | M3: 75000 | N3: 17857 | O3: 25000 | P3: 100000 | Q3: 70000 | R3: 30000 | S3: 0 | T3: 0 | U3: 0.7 | V3: 1 | W3: 0 | X3: 0 | Y3: 0 | Z3: 0 | AA3: 0 | AB3: 0 | AC3: 0 | AD3: 0 | AE3: 0 | AF3: 0.7 | AG3: 1
A4: AZ1116YGTTA4EA01WQ | B4: Scorpio-N | C4: Z8 L D AT 2WD 7 STR BS6.2 - N - ADAS | D4: 1557827 | E4: 40 | F4: 623131 | G4: 2180958 | H4: 68245 | I4: 0 | J4: 27298 | K4: 2276500 | L4: 53571 | M4: 75000 | N4: 17857 | O4: 25000 | P4: 100000 | Q4: 70000 | R4: 30000 | S4: 0 | T4: 0 | U4: 0.7 | V4: 1 | W4: 0 | X4: 0 | Y4: 0 | Z4: 0 | AA4: 0 | AB4: 0 | AC4: 0 | AD4: 0 | AE4: 0 | AF4: 0.7 | AG4: 1
A5: AZ1116YGTTA4EA01SG | B5: Scorpio-N | C5: Z8 L D AT 2WD 7 STR BS6.2 - N - ADAS | D5: 1557827 | E5: 40 | F5: 623131 | G5: 2180958 | H5: 68245 | I5: 0 | J5: 27298 | K5: 2276500 | L5: 53571 | M5: 75000 | N5: 17857 | O5: 25000 | P5: 100000 | Q5: 70000 | R5: 30000 | S5: 0 | T5: 0 | U5: 0.7 | V5: 1 | W5: 0 | X5: 0 | Y5: 0 | Z5: 0 | AA5: 0 | AB5: 0 | AC5: 0 | AD5: 0 | AE5: 0 | AF5: 0.7 | AG5: 1
A6: AZ1116YGTTA4EA01JD | B6: Scorpio-N | C6: Z8 L D AT 2WD 7 STR BS6.2 - N - ADAS | D6: 1557827 | E6: 40 | F6: 623131 | G6: 2180958 | H6: 68245 | I6: 0 | J6: 27298 | K6: 2276500 | L6: 53571 | M6: 75000 | N6: 17857 | O6: 25000 | P6: 100000 | Q6: 70000 | R6: 30000 | S6: 0 | T6: 0 | U6: 0.7 | V6: 1 | W6: 0 | X6: 0 | Y6: 0 | Z6: 0 | AA6: 0 | AB6: 0 | AC6: 0 | AD6: 0 | AE6: 0 | AF6: 0.7 | AG6: 1
A7: AZ1116YGTTA4EA01XJ | B7: Scorpio-N | C7: Z8 L D AT 2WD 7 STR BS6.2 - N - ADAS | D7: 1557827 | E7: 40 | F7: 623131 | G7: 2180958 | H7: 68245 | I7: 0 | J7: 27298 | K7: 2276500 | L7: 53571 | M7: 75000 | N7: 17857 | O7: 25000 | P7: 100000 | Q7: 70000 | R7: 30000 | S7: 0 | T7: 0 | U7: 0.7 | V7: 1 | W7: 0 | X7: 0 | Y7: 0 | Z7: 0 | AA7: 0 | AB7: 0 | AC7: 0 | AD7: 0 | AE7: 0 | AF7: 0.7 | AG7: 1
A8: AZ1116YGTTA2EA01BZ | B8: Scorpio-N | C8: Z8 L D AT 2WD 6 STR BS6.2 - N - ADAS | D8: 1572843 | E8: 40 | F8: 629137 | G8: 2201980 | H8: 68943 | I8: 0 | J8: 27577 | K8: 2298500 | L8: 53571 | M8: 75000 | N8: 17857 | O8: 25000 | P8: 100000 | Q8: 70000 | R8: 30000 | S8: 0 | T8: 0 | U8: 0.7 | V8: 1 | W8: 0 | X8: 0 | Y8: 0 | Z8: 0 | AA8: 0 | AB8: 0 | AC8: 0 | AD8: 0 | AE8: 0 | AF8: 0.7 | AG8: 1
A9: AZ1116YGTTA2EA01WQ | B9: Scorpio-N | C9: Z8 L D AT 2WD 6 STR BS6.2 - N - ADAS | D9: 1572843 | E9: 40 | F9: 629137 | G9: 2201980 | H9: 68943 | I9: 0 | J9: 27577 | K9: 2298500 | L9: 53571 | M9: 75000 | N9: 17857 | O9: 25000 | P9: 100000 | Q9: 70000 | R9: 30000 | S9: 0 | T9: 0 | U9: 0.7 | V9: 1 | W9: 0 | X9: 0 | Y9: 0 | Z9: 0 | AA9: 0 | AB9: 0 | AC9: 0 | AD9: 0 | AE9: 0 | AF9: 0.7 | AG9: 1
A10: AZ1116YGTTA2EA01SG | B10: Scorpio-N | C10: Z8 L D AT 2WD 6 STR BS6.2 - N - ADAS | D10: 1572843 | E10: 40 | F10: 629137 | G10: 2201980 | H10: 68943 | I10: 0 | J10: 27577 | K10: 2298500 | L10: 53571 | M10: 75000 | N10: 17857 | O10: 25000 | P10: 100000 | Q10: 70000 | R10: 30000 | S10: 0 | T10: 0 | U10: 0.7 | V10: 1 | W10: 0 | X10: 0 | Y10: 0 | Z10: 0 | AA10: 0 | AB10: 0 | AC10: 0 | AD10: 0 | AE10: 0 | AF10: 0.7 | AG10: 1
A11: AZ1116YGTTA2EA01JD | B11: Scorpio-N | C11: Z8 L D AT 2WD 6 STR BS6.2 - N - ADAS | D11: 1572843 | E11: 40 | F11: 629137 | G11: 2201980 | H11: 68943 | I11: 0 | J11: 27577 | K11: 2298500 | L11: 53571 | M11: 75000 | N11: 17857 | O11: 25000 | P11: 100000 | Q11: 70000 | R11: 30000 | S11: 0 | T11: 0 | U11: 0.7 | V11: 1 | W11: 0 | X11: 0 | Y11: 0 | Z11: 0 | AA11: 0 | AB11: 0 | AC11: 0 | AD11: 0 | AE11: 0 | AF11: 0.7 | AG11: 1
A12: AZ1116YGTTA2EA01XJ | B12: Scorpio-N | C12: Z8 L D AT 2WD 6 STR BS6.2 - N - ADAS | D12: 1572843 | E12: 40 | F12: 629137 | G12: 2201980 | H12: 68943 | I12: 0 | J12: 27577 | K12: 2298500 | L12: 53571 | M12: 75000 | N12: 17857 | O12: 25000 | P12: 100000 | Q12: 70000 | R12: 30000 | S12: 0 | T12: 0 | U12: 0.7 | V12: 1 | W12: 0 | X12: 0 | Y12: 0 | Z12: 0 | AA12: 0 | AB12: 0 | AC12: 0 | AD12: 0 | AE12: 0 | AF12: 0.7 | AG12: 1
A13: AZ1118YGTTA4EA01BZ | B13: Scorpio-N | C13: Z8 L D AT 4WD 7 STR BS6.2 - N - ADAS | D13: 1707343 | E13: 40 | F13: 682937 | G13: 2390281 | H13: 74800 | I13: 0 | J13: 29920 | K13: 2495000 | L13: 89286 | M13: 125000 | N13: 17857 | O13: 25000 | P13: 150000 | Q13: 120000 | R13: 30000 | S13: 0 | T13: 0 | U13: 0.7 | V13: 1 | W13: 0 | X13: 0 | Y13: 0 | Z13: 0 | AA13: 0 | AB13: 0 | AC13: 0 | AD13: 0 | AE13: 0 | AF13: 0.7 | AG13: 1
A14: AZ1118YGTTA4EA01WQ | B14: Scorpio-N | C14: Z8 L D AT 4WD 7 STR BS6.2 - N - ADAS | D14: 1707343 | E14: 40 | F14: 682937 | G14: 2390281 | H14: 74800 | I14: 0 | J14: 29920 | K14: 2495000 | L14: 89286 | M14: 125000 | N14: 17857 | O14: 25000 | P14: 150000 | Q14: 120000 | R14: 30000 | S14: 0 | T14: 0 | U14: 0.7 | V14: 1 | W14: 0 | X14: 0 | Y14: 0 | Z14: 0 | AA14: 0 | AB14: 0 | AC14: 0 | AD14: 0 | AE14: 0 | AF14: 0.7 | AG14: 1
... A18: AW5068YLTTB1UC01QL | B18: Thar | C18: LXT D AT 4WD 4S HT BS6.2 | D18: 1211983 | E18: 40 | F18: 484793 | G18: 1696777 | H18: 73374 | I18: 0 | J18: 29350 | K18: 1799501 | L18: 14286 | M18: 20000 | N18: 0 | O18: 0 | P18: 20000 | Q18: 10000 | R18: 10000 | S18: 0 | T18: 0 | U18: 0.7 | V18: 1 | W18: 0 | X18: 0 | Y18: 0 | Z18: 0 | AA18: 0 | AB18: 0 | AC18: 0 | AD18: 0 | AE18: 0 | AF18: 0.7 | AG18: 1

Sheet Price List CV
L1: Current VIN | W1: Old VIN
A2: Model Code | B2: OEM Model | C2: OEM Variant | D2: Asse Value with Freight | E2: GST | F2: GST Amount | G2: MM Inv Amt | H2: Dealer Margin | I2: Dealer Handling | J2: GST Amount 1 | K2: Ex-Showroom Price ORG | L2: OEM Scheme @ BNDP | M2: OEM Scheme with GST | N2: Dealer Cont @ BNDP | O2: Dealer Contribution with GST | P2: Total Consumer Scheme with GST (OEM + Dealer) | Q2: Cash Discount | R2: Accessories Discount | S2: Shield Discount | T2: Check | U2: Acc Dsc Elg | V2: Sheld Disc Elg | W2: OEM Scheme @ BNDP | X2: OEM Scheme with GST | Y2: Dealer Cont @ BNDP | Z2: Dealer Contribution with GST | AA2: Total Consumer Scheme with GST (OEM + Dealer) | AB2: Cash Discount | AC2: Accessories Discount | AD2: Shield Discount | AE2: Check | AF2: Acc Dsc Elg | AG2: Sheld Disc Elg
A3: G2C4AACVXB3C1C01QT | B3: VEERO | C3: 1.6XXL CBC V2 | D3: 669909 | E3: 18 | F3: 120584 | G3: 790493 | H3: 0 | I3: 28820 | J3: 5188 | K3: 824500 | L3: 46610 | M3: 55000 | N3: 0 | O3: 0 | P3: =M3+O3 -> 55000 | Q3: 35000 | R3: 20000 | S3: 0 | T3: =P3-SUM(Q3:S3) -> 0 | U3: 0.7 | V3: 1 | W3: 0 | X3: 0 | Y3: 0 | Z3: 0 | AA3: =X3+Z3 -> 0 | AB3: 0 | AC3: 0 | AD3: 0 | AE3: =AA3-SUM(AB3:AD3) -> 0 | AF3: 0.7 | AG3: 1
A4: G2D4AACVXB3F1A01WT | B4: VEERO | C4: 1.5XXL SD V2 - Airbag | D4: 693517 | E4: 18 | F4: 124833 | G4: 818350 | H4: 0 | I4: 29788 | J4: 5362 | K4: 853500 | L4: 46610 | M4: 55000 | N4: 0 | O4: 0 | P4: =M4+O4 -> 55000 | Q4: 35000 | R4: 20000 | S4: 0 | T4: =P4-SUM(Q4:S4) -> 0 | U4: 0.7 | V4: 1 | W4: 0 | X4: 0 | Y4: 0 | Z4: 0 | AA4: =X4+Z4 -> 0 | AB4: 0 | AC4: 0 | AD4: 0 | AE4: =AA4-SUM(AB4:AD4) -> 0 | AF4: 0.7 | AG4: 1
A5: G2D4AACVXB3F1A01QT | B5: VEERO | C5: 1.5XXL SD V2 - Airbag | D5: 693517 | E5: 18 | F5: 124833 | G5: 818350 | H5: 0 | I5: 29788 | J5: 5362 | K5: 853500 | L5: 46610 | M5: 55000 | N5: 0 | O5: 0 | P5: =M5+O5 -> 55000 | Q5: 35000 | R5: 20000 | S5: 0 | T5: =P5-SUM(Q5:S5) -> 0 | U5: 0.7 | V5: 1 | W5: 0 | X5: 0 | Y5: 0 | Z5: 0 | AA5: =X5+Z5 -> 0 | AB5: 0 | AC5: 0 | AD5: 0 | AE5: =AA5-SUM(AB5:AD5) -> 0 | AF5: 0.7 | AG5: 1
A6: PKN2BAADBS6PSFA3WD | B6: MAXX CITY | C6: MAXX CITY 1.3 LX BS6.2 - Special Edition | D6: 621615 | E6: 18 | F6: 111891 | G6: 733506 | H6: 0 | I6: 33215 | J6: 5979 | K6: 772700 | L6: 33898 | M6: 40000 | N6: 0 | O6: 0 | P6: =M6+O6 -> 40000 | Q6: 25000 | R6: 15000 | S6: 0 | T6: =P6-SUM(Q6:S6) -> 0 | U6: 0.7 | V6: 1 | W6: 0 | X6: 0 | Y6: 0 | Z6: 0 | AA6: =X6+Z6 -> 0 | AB6: 0 | AC6: 0 | AD6: 0 | AE6: =AA6-SUM(AB6:AD6) -> 0 | AF6: 0.7 | AG6: 1
A7: G2E4AACUXB3F1A01WT | B7: VEERO | C7: 1.5XXL SD V4 - Airbag | D7: 717041 | E7: 18 | F7: 129067 | G7: 846108 | H7: 0 | I7: 30840 | J7: 5551 | K7: 882500 | L7: 38136 | M7: 45000 | N7: 0 | O7: 0 | P7: =M7+O7 -> 45000 | Q7: 25000 | R7: 20000 | S7: 0 | T7: =P7-SUM(Q7:S7) -> 0 | U7: 0.7 | V7: 1 | W7: 0 | X7: 0 | Y7: 0 | Z7: 0 | AA7: =X7+Z7 -> 0 | AB7: 0 | AC7: 0 | AD7: 0 | AE7: =AA7-SUM(AB7:AD7) -> 0 | AF7: 0.7 | AG7: 1
A8: G2C4AACVXB3C1A01WT | B8: VEERO | C8: 1.5XXL CBC V2 | D8: 669909 | E8: 18 | F8: 120584 | G8: 790493 | H8: 0 | I8: 28820 | J8: 5188 | K8: 824500 | L8: 46610 | M8: 55000 | N8: 0 | O8: 0 | P8: =M8+O8 -> 55000 | Q8: 35000 | R8: 20000 | S8: 0 | T8: =P8-SUM(Q8:S8) -> 0 | U8: 0.7 | V8: 1 | W8: 0 | X8: 0 | Y8: 0 | Z8: 0 | AA8: =X8+Z8 -> 0 | AB8: 0 | AC8: 0 | AD8: 0 | AE8: =AA8-SUM(AB8:AD8) -> 0 | AF8: 0.7 | AG8: 1
A9: G2C4AACVXB3C1A01QT | B9: VEERO | C9: 1.5XXL CBC V2 | D9: 669909 | E9: 18 | F9: 120584 | G9: 790493 | H9: 0 | I9: 28820 | J9: 5188 | K9: 824500 | L9: 46610 | M9: 55000 | N9: 0 | O9: 0 | P9: =M9+O9 -> 55000 | Q9: 35000 | R9: 20000 | S9: 0 | T9: =P9-SUM(Q9:S9) -> 0 | U9: 0.7 | V9: 1 | W9: 0 | X9: 0 | Y9: 0 | Z9: 0 | AA9: =X9+Z9 -> 0 | AB9: 0 | AC9: 0 | AD9: 0 | AE9: =AA9-SUM(AB9:AD9) -> 0 | AF9: 0.7 | AG9: 1
A10: G2C4AACVXB3C1C01WT | B10: VEERO | C10: 1.6XXL CBC V2 | D10: 669909 | E10: 18 | F10: 120584 | G10: 790493 | H10: 0 | I10: 28820 | J10: 5188 | K10: 824500 | L10: 46610 | M10: 55000 | N10: 0 | O10: 0 | P10: =M10+O10 -> 55000 | Q10: 35000 | R10: 20000 | S10: 0 | T10: =P10-SUM(Q10:S10) -> 0 | U10: 0.7 | V10: 1 | W10: 0 | X10: 0 | Y10: 0 | Z10: 0 | AA10: =X10+Z10 -> 0 | AB10: 0 | AC10: 0 | AD10: 0 | AE10: =AA10-SUM(AB10:AD10) -> 0 | AF10: 0.7 | AG10: 1

Sheet Price List BEV
L1: Current VIN | W1: Old VIN
A2: Model Code | B2: OEM Model | C2: OEM Variant | D2: Asse Value with Freight | E2: GST | F2: GST Amount | G2: MM Inv Amt | H2: Dealer Margin | I2: Dealer Handling | J2: GST Amount 1 | K2: Ex-Showroom Price ORG | L2: OEM Scheme @ BNDP | M2: OEM Scheme with GST | N2: Dealer Cont @ BNDP | O2: Dealer Contribution with GST | P2: Total Consumer Scheme with GST (OEM + Dealer) | Q2: Cash Discount | R2: Accessories Discount | S2: Shield Discount | T2: Check | U2: Acc Dsc Elg | V2: Sheld Disc Elg | W2: OEM Scheme @ BNDP | X2: OEM Scheme with GST | Y2: Dealer Cont @ BNDP | Z2: Dealer Contribution with GST | AA2: Total Consumer Scheme with GST (OEM + Dealer) | AB2: Cash Discount | AC2: Accessories Discount | AD2: Shield Discount | AE2: Check | AF2: Acc Dsc Elg | AG2: Sheld Disc Elg
A3: BW62AB717MC01D02BN | B3: XEV9S | C3: XEV 9S TWO ABOVE B79 R18 7STR NCH | D3: 2393579 | E3: 5 | F3: 119679 | G3: 2513258 | H3: 77850 | I3: 0 | J3: 3893 | K3: 2595001 | L3: 0 | M3: 0 | N3: 0 | O3: 0 | P3: 0 | Q3: 0 | R3: =P3-Q3 -> 0 | S3: =P3-Q3-R3 -> 0 | T3: 0 | U3: 0.7 | V3: 1 | W3: 0 | X3: 0 | Y3: 0 | Z3: 0 | AA3: 0 | AB3: 0 | AC3: 0 | AD3: 0 | AE3: 0 | AF3: 0.7 | AG3: 1
A4: BM32AB715MB01D00WQ | B4: XEV9E | C4: XEV 9E TWO B79 R19 C11 | D4: 2513488 | E4: 5 | F4: 125674 | G4: 2639162 | H4: 81750 | I4: 0 | J4: 4088 | K4: 2725000 | L4: 66667 | M4: 70000 | N4: 19048 | O4: 20000 | P4: 90000 | Q4: 70000 | R4: 0 | S4: 0 | T4: 20000 | U4: 0.7 | V4: 1 | W4: 0 | X4: 0 | Y4: 0 | Z4: 0 | AA4: 0 | AB4: 0 | AC4: 0 | AD4: 0 | AE4: 0 | AF4: 0.7 | AG4: 1
A5: BM32AB715MB01D02RV | B5: XEV9E | C5: XEV 9E TWO B79 R19 NCH | D5: 2444310 | E5: 5 | F5: 122216 | G5: 2566526 | H5: 79500 | I5: 0 | J5: 3975 | K5: 2650001 | L5: 66667 | M5: 70000 | N5: 19048 | O5: 20000 | P5: 90000 | Q5: 70000 | R5: 0 | S5: 0 | T5: 20000 | U5: 0.7 | V5: 1 | W5: 0 | X5: 0 | Y5: 0 | Z5: 0 | AA5: 0 | AB5: 0 | AC5: 0 | AD5: 0 | AE5: 0 | AF5: 0.7 | AG5: 1
A6: BM32AF715MB01F02XM | B6: XEV9E | C6: XEV 9e THREE CL B79 R19 NCH | D6: 2707188 | E6: 5 | F6: 135359 | G6: 2842547 | H6: 88050 | I6: 0 | J6: 4403 | K6: 2935000 | L6: 0 | M6: 0 | N6: 0 | O6: 0 | P6: 0 | Q6: 0 | R6: 0 | S6: 0 | T6: 0 | U6: 0.7 | V6: 1 | W6: 0 | X6: 0 | Y6: 0 | Z6: 0 | AA6: 0 | AB6: 0 | AC6: 0 | AD6: 0 | AE6: 0 | AF6: 0.7 | AG6: 1
A7: BM12AQ715MB01B02OG | B7: BE6 FE | C7: BE 6 FE3 B79 R20 NCH | D7: 2258909 | E7: 5 | F7: 112945 | G7: 2371854 | H7: 73470 | I7: 0 | J7: 3674 | K7: 2448998 | L7: 95238 | M7: 100000 | N7: 0 | O7: 0 | P7: 100000 | Q7: 80000 | R7: 0 | S7: 0 | T7: 20000 | U7: 0.7 | V7: 1 | W7: 0 | X7: 0 | Y7: 0 | Z7: 0 | AA7: 0 | AB7: 0 | AC7: 0 | AD7: 0 | AE7: 0 | AF7: 0.7 | AG7: 1
A8: BW62AC717MB01D00WQ | B8: XEV9S | C8: XEV 9S THREE B79 R18 7STR C11 | D8: 2638010 | E8: 5 | F8: 131901 | G8: 2769911 | H8: 85800 | I8: 0 | J8: 4290 | K8: 2860001 | L8: 0 | M8: 0 | N8: 0 | O8: 0 | P8: 0 | Q8: 0 | R8: 0 | S8: 0 | T8: 0 | U8: 0.7 | V8: 1 | W8: 0 | X8: 0 | Y8: 0 | Z8: 0 | AA8: 0 | AB8: 0 | AC8: 0 | AD8: 0 | AE8: 0 | AF8: 0.7 | AG8: 1
A9: BM12AH515MB02D02OG | B9: BE6 | C9: BE 6 One above B59 R19 NCH | D9: 1890882 | E9: 5 | F9: 94544 | G9: 1985426 | H9: 61500 | I9: 0 | J9: 3075 | K9: 2050001 | L9: 57143 | M9: 60000 | N9: 19048 | O9: 20000 | P9: 80000 | Q9: 60000 | R9: 0 | S9: 0 | T9: 20000 | U9: 0.7 | V9: 1 | W9: 0 | X9: 0 | Y9: 0 | Z9: 0 | AA9: 0 | AB9: 0 | AC9: 0 | AD9: 0 | AE9: 0 | AF9: 0.7 | AG9: 1
A10: BW62AD717MB01D02WQ | B10: XEV9S | C10: XEV 9S THREE ABOVE B79 R18 7STR NCH | D10: 2762531 | E10: 5 | F10: 138127 | G10: 2900658 | H10: 89850 | I10: 0 | J10: 4493 | K10: 2995000 | L10: 0 | M10: 0 | N10: 0 | O10: 0 | P10: 0 | Q10: 0 | R10: 0 | S10: 0 | T10: 0 | U10: 0.7 | V10: 1 | W10: 0 | X10: 0 | Y10: 0 | Z10: 0 | AA10: 0 | AB10: 0 | AC10: 0 | AD10: 0 | AE10: 0 | AF10: 0.7 | AG10: 1
A11: BM12AB515MB02D02XJ | B11: BE6 | C11: BE 6 Two B59 R19 NCH | D11: 2020015 | E11: 5 | F11: 101001 | G11: 2121016 | H11: 65700 | I11: 0 | J11: 3285 | K11: 2190001 | L11: 123810 | M11: 130001 | N11: 19048 | O11: 20000 | P11: 150001 | Q11: 130000 | R11: 0 | S11: 0 | T11: 20001 | U11: 0.7 | V11: 1 | W11: 0 | X11: 0 | Y11: 0 | Z11: 0 | AA11: 0 | AB11: 0 | AC11: 0 | AD11: 0 | AE11: 0 | AF11: 0.7 | AG11: 1

Sheet Price List LMM
A1: City | B1: OEM Model | C1: OEM Variant | D1: Model Code | E1: Assesable Value | F1: Freight New | G1: GST% | H1: Cess% | I1: GST Amount | J1: LMM Inv Amt | K1: New Dealer Margin | L1: Extra Handling | M1: GST Amount 1 | N1: Ex Showroom Price | O1: Ex Showroom Price(Org) | P1: VIN Scheme | R1: OEM Scheme @ BNDP | S1: Dealer Cont @ BNDP | T1: Dealer Contribution with GST | U1: Total Consumer Scheme with GST (OEM + Dealer)
A2: BIKANER | B2: E ALFA PLUS | C2: E-ALFA+ SOLT WT | D2: 1EV2DH5T3FZG1WS | E2: 151038 | F2: 4559 | G2: 5 | H2: 0 | I2: 7780 | J2: 163376 | K2: 10327 | L2: 0 | M2: 516 | N2: 174219 | O2: 177219 | P2: 10876 | R2: =P2/(100%+G2%) -> 10358.095 | S2: =T2/(100%+G2%) -> 2880 | T2: 3024 | U2: =P2+T2 -> 13900
A3: BIKANER | B3: E ALFA PLUS | C3: E-ALFA+ WARM RED | D3: 1EV2DH5T3FZG1WR | E3: 151038 | F3: 4559 | G3: 5 | H3: 0 | I3: 7780 | J3: 163376 | K3: 10327 | L3: 0 | M3: 516 | N3: 174219 | O3: 177219 | P3: 10876 | R3: =P3/(100%+G3%) -> 10358.095 | S3: =T3/(100%+G3%) -> 2880 | T3: 3024 | U3: =P3+T3 -> 13900
A4: BIKANER | B4: E ALFA PLUS | C4: E-ALFA+ NISS BLU | D4: 1EV2DH5T3FZG1NB | E4: 151038 | F4: 4559 | G4: 5 | H4: 0 | I4: 7780 | J4: 163376 | K4: 10327 | L4: 0 | M4: 516 | N4: 174219 | O4: 177219 | P4: 10876 | R4: =P4/(100%+G4%) -> 10358.095 | S4: =T4/(100%+G4%) -> 2880 | T4: 3024 | U4: =P4+T4 -> 13900
A5: BIKANER | B5: ZEO | C5: MAHINDRA ZEO V2 | D5: AP61WLED2BB18A00WD | E5: 7,26,023 | F5: 10011 | G5: 5 | H5: - | I5: 36802 | J5: 7,72,836 | K5: 31663 | L5: 0 | M5: 1583 | N5: 8,06,081 | O5: 8,06,081 | P5: 0 | R5: =P5/(100%+G5%) -> 0 | S5: =T5/(100%+G5%) -> 0 | U5: =P5+T5 -> 0
A6: BIKANER | B6: ZEO | C6: MAHINDRA ZEO V2-DEMO | D6: AP61WLED2BB18A99WD | E6: 7,26,023 | F6: 10011 | G6: 5 | H6: - | I6: 36802 | J6: 7,72,836 | K6: 31663 | L6: 0 | M6: 1583 | N6: 8,06,081 | O6: 8,06,081 | P6: 0 | R6: =P6/(100%+G6%) -> 0 | S6: =T6/(100%+G6%) -> 0 | U6: =P6+T6 -> 0
A7: BIKANER | B7: ZEO | C7: MAHINDRA ZEO V2 DV 200 | D7: AP61WLED2BB18J00WD | E7: 7,36,319 | F7: 29122 | G7: 5 | H7: - | I7: 38272 | J7: 8,03,713 | K7: 31640 | L7: 0 | M7: 1582 | N7: 8,36,935 | O7: 8,36,935 | P7: 0 | R7: =P7/(100%+G7%) -> 0 | S7: =T7/(100%+G7%) -> 0 | U7: =P7+T7 -> 0
A8: BIKANER | B8: ZEO | C8: MAHINDRA ZEO V2 DV 200-DEMO | D8: AP61WLED2BB18J99WD | E8: 7,36,319 | F8: 29122 | G8: 5 | H8: - | I8: 38272 | J8: 8,03,713 | K8: 31640 | L8: 0 | M8: 1582 | N8: 8,36,935 | O8: 8,36,935 | P8: 0 | R8: =P8/(100%+G8%) -> 0 | S8: =T8/(100%+G8%) -> 0 | U8: =P8+T8 -> 0

Sheet Price List LMM TZU
A1: City | B1: M.CODE | C1: Material Description | D1: Model Name | E1: Model Group | F1: Scheme | G1: Before GST | H1: New Base Price (Ex-Factory) | I1: Freight | J1: Diff/Adjustment | K1: Assessable Value | L1: GST on Assessable Value @ 5% | M1: LMM Billing Price before (PM E-DRIVE SUBSIDY) | N1: LMM Billing Price After (PM E-DRIVE SUBSIDY) | O1: New Dealer Marging | P1: Dealer GST @ 5% | Q1: Ex-Showroom Pre Subsidy | R1: Battery Capacity | S1: PM E-DRIVE SUBSIDY Subsidy | T1: Maharashtra State Subsidy | U1: Exshowroom Post Subsidy (PM E-DRIVE SUBSIDY) | V1: Scheme | W1: Final Transaction Price | Y1: OEM Scheme @ BNDP | Z1: Dealer Cont @ BNDP | AA1: Dealer Contribution with GST | AB1: Total Consumer Scheme with GST (OEM + Dealer)
A2: BIKANER | B2: 0000AMJ00030N | C2: TREO HRT | D2: TREO HRT | E2: TREO AUTO | F2: 20000 | G2: 19048 | H2: 3,00,752 | I2: 11875 | J2: - | K2: 3,12,627 | L2: 15631 | M2: 3,28,258 | N2: 3,28,258 | O2: 19518 | P2: 976 | Q2: 3,48,752 | U2: 3,48,752 | V2: 20000 | W2: 3,28,752 | Y2: =V2/(100%+5%) -> 19047.619 | Z2: =AA2/(100%+5%) -> 0 | AA2: 0 | AB2: =V2+AA2 -> 20000
A3: BIKANER | B3: 0000AMJ00030N | C3: TREO HRT | D3: TREO HRT | E3: TREO AUTO | F3: 20000 | G3: 19048 | H3: 3,00,752 | I3: 11875 | J3: - | K3: 3,12,627 | L3: 15631 | M3: 3,28,258 | N3: 3,28,258 | O3: 19518 | P3: 976 | Q3: 3,48,752 | U3: 3,48,752 | V3: 20000 | W3: 3,28,752 | Y3: =V3/(100%+5%) -> 19047.619 | Z3: =AA3/(100%+5%) -> 0 | AA3: 0 | AB3: =V3+AA3 -> 20000
A4: BIKANER | B4: 0000AMJ00010N | C4: TREO SFT | D4: TREO SFT | E4: TREO AUTO | F4: 20000 | G4: 19048 | H4: 2,90,794 | I4: 11875 | J4: - | K4: 3,02,669 | L4: 15133 | M4: 3,17,802 | N4: 3,17,802 | O4: 19625 | P4: 981 | Q4: 3,38,408 | U4: 3,38,408 | V4: 20000 | W4: 3,18,408 | Y4: =V4/(100%+5%) -> 19047.619 | Z4: =AA4/(100%+5%) -> 0 | AA4: 0 | AB4: =V4+AA4 -> 20000
A5: BIKANER | B5: 1EP2GN4TVNUG1TW | C5: UDO ST | D5: UDO ST | E5: UDO | F5: 25300 | G5: 24095 | H5: 3,45,095 | I5: 14000 | J5: - | K5: 3,59,095 | L5: 17955 | M5: 3,77,050 | N5: 3,77,050 | O5: 17000 | P5: 850 | Q5: 3,94,900 | U5: 3,94,900 | V5: 25300 | W5: 3,69,600 | Y5: =V5/(100%+5%) -> 24095.238 | Z5: =AA5/(100%+5%) -> 0 | AA5: 0 | AB5: =V5+AA5 -> 25300
A6: BIKANER | B6: 1EP2GN4TVNUG1WS | C6: UDO ST | D6: UDO ST | E6: UDO | F6: 25300 | G6: 24095 | H6: 3,45,095 | I6: 14000 | J6: - | K6: 3,59,095 | L6: 17955 | M6: 3,77,050 | N6: 3,77,050 | O6: 17000 | P6: 850 | Q6: 3,94,900 | U6: 3,94,900 | V6: 25300 | W6: 3,69,600 | Y6: =V6/(100%+5%) -> 24095.238 | Z6: =AA6/(100%+5%) -> 0 | AA6: 0 | AB6: =V6+AA6 -> 25300
A7: BIKANER | B7: 1EP2GN4TVNUG1YB | C7: UDO ST | D7: UDO ST | E7: UDO | F7: 25300 | G7: 24095 | H7: 3,45,095 | I7: 14000 | J7: - | K7: 3,59,095 | L7: 17955 | M7: 3,77,050 | N7: 3,77,050 | O7: 17000 | P7: 850 | Q7: 3,94,900 | U7: 3,94,900 | V7: 25300 | W7: 3,69,600 | Y7: =V7/(100%+5%) -> 24095.238 | Z7: =AA7/(100%+5%) -> 0 | AA7: 0 | AB7: =V7+AA7 -> 25300

Sheet Price List CSD
K1: 1- Basic Price to CSD | M1: 2 - Discount to CSD | N1: 3 - Consumer Scheme Before GST | O1: 4 - Net Price Before GST | P1: 5 - GST Rate | Q1: 6 - GST Amount | R1: 7 - Invoice Amt (Ex SR Price) (LS OrderAmt) | U1: 9 - GST Discount @ 50% | V1: 8 - CSD Charge @ 0.5% | W1: 10 - DD Amount (Inclusive of CSD Charge)
A2: Model Code | B2: OEM Model | C2: OEM Variant | D2: Custom Model | E2: Custom Variant | F2: Display Name | G2: City | H2: Asse Value with Freight | I2: Retail Dealer Margin | J2: DEALER MARGIN DISCOUNT | K2: BASIC Price Including CSD Dealer Margin | L2: CSD% Discount | M2: CSD Discount | N2: Market Scheme at BNDP | O2: CSD Basic with Discount | P2: GST % | Q2: GST Amount | R2: CSD Final Price | S2: Amount to be claimed by Dealer | T2: GST @ 50% Discount | U2: GST Amount on CSD Basic with Discount | V2: CSD Profit @ 0.50% | W2: CSD Final Price with GST Concession
A3: BM12AJ515MB01B00RQ | B3: BE6 | C3: BE 6 Three Select B59 R19 C11 | D3: =VLOOKUP($A3,'Vehicle Info'!$A:$W,18,0) -> #N/A | E3: =VLOOKUP($A3,'Vehicle Info'!$A:$W,19,0) -> #N/A | F3: =VLOOKUP($A3,'Vehicle Info'!$A:$W,20,0) -> #N/A | G3: BIKANER | H3: 23,29,012 | I3: 75750 | J3: 38200 | K3: 23,66,562 | L3: 0.27 | M3: 6288 | N3: 66667 | O3: 22,93,607 | P3: 5 | Q3: 1,14,680 | R3: 24,08,288 | S3: 6603 | T3: 2.5 | U3: 57340 | V3: 11468 | W3: 23,62,415
A4: BM12AJ515MB01B00XJ | B4: BE6 | C4: BE 6 Three Select B59 R19 C11 | D4: =VLOOKUP($A4,'Vehicle Info'!$A:$W,18,0) -> #N/A | E4: =VLOOKUP($A4,'Vehicle Info'!$A:$W,19,0) -> #N/A | F4: =VLOOKUP($A4,'Vehicle Info'!$A:$W,20,0) -> #N/A | G4: BIKANER | H4: 23,29,012 | I4: 75750 | J4: 38200 | K4: 23,66,562 | L4: 0.27 | M4: 6288 | N4: 66667 | O4: 22,93,607 | P4: 5 | Q4: 1,14,680 | R4: 24,08,288 | S4: 6603 | T4: 2.5 | U4: 57340 | V4: 11468 | W4: 23,62,415
A5: BM12AJ515MB01B00OG | B5: BE6 | C5: BE 6 Three Select B59 R19 C11 | D5: =VLOOKUP($A5,'Vehicle Info'!$A:$W,18,0) -> #N/A | E5: =VLOOKUP($A5,'Vehicle Info'!$A:$W,19,0) -> #N/A | F5: =VLOOKUP($A5,'Vehicle Info'!$A:$W,20,0) -> #N/A | G5: BIKANER | H5: 23,29,012 | I5: 75750 | J5: 38200 | K5: 23,66,562 | L5: 0.27 | M5: 6288 | N5: 66667 | O5: 22,93,607 | P5: 5 | Q5: 1,14,680 | R5: 24,08,288 | S5: 6603 | T5: 2.5 | U5: 57340 | V5: 11468 | W5: 23,62,415
A6: BM12AJ515MB01B00QK | B6: BE6 | C6: BE 6 Three Select B59 R19 C11 | D6: =VLOOKUP($A6,'Vehicle Info'!$A:$W,18,0) -> #N/A | E6: =VLOOKUP($A6,'Vehicle Info'!$A:$W,19,0) -> #N/A | F6: =VLOOKUP($A6,'Vehicle Info'!$A:$W,20,0) -> #N/A | G6: BIKANER | H6: 23,29,012 | I6: 75750 | J6: 38200 | K6: 23,66,562 | L6: 0.27 | M6: 6288 | N6: 66667 | O6: 22,93,607 | P6: 5 | Q6: 1,14,680 | R6: 24,08,288 | S6: 6603 | T6: 2.5 | U6: 57340 | V6: 11468 | W6: 23,62,415
A7: AZ1036YJT2A4FA01SF | B7: Scorpio-N | C7: Z2 D MT 2WD 7 STR - E BS6.2 - New | D7: =VLOOKUP($A7,'Vehicle Info'!$A:$W,18,0) -> #N/A | E7: =VLOOKUP($A7,'Vehicle Info'!$A:$W,19,0) -> #N/A | F7: =VLOOKUP($A7,'Vehicle Info'!$A:$W,20,0) -> #N/A | G7: BIKANER | H7: 9,57,358 | I7: 41928 | J7: 4416 | K7: 9,94,869 | L7: 1 | M7: 9574 | N7: - | O7: 9,85,296 | P7: 40 | Q7: 3,94,118 | R7: 13,79,414 | S7: 13403 | T7: 20 | U7: 1,97,059 | V7: 4926 | W7: 11,87,281
A8: AZ1036YJT2A4FA01XH | B8: Scorpio-N | C8: Z2 D MT 2WD 7 STR - E BS6.2 - New | D8: =VLOOKUP($A8,'Vehicle Info'!$A:$W,18,0) -> #N/A | E8: =VLOOKUP($A8,'Vehicle Info'!$A:$W,19,0) -> #N/A | F8: =VLOOKUP($A8,'Vehicle Info'!$A:$W,20,0) -> #N/A | G8: BIKANER | H8: 9,57,358 | I8: 41928 | J8: 4416 | K8: 9,94,869 | L8: 1 | M8: 9574 | N8: - | O8: 9,85,296 | P8: 40 | Q8: 3,94,118 | R8: 13,79,414 | S8: 13403 | T8: 20 | U8: 1,97,059 | V8: 4926 | W8: 11,87,281
A9: AZ1096YJT2A4FA01WQ | B9: Scorpio-N | C9: Z2 D MT 2WD 7 STR - E BS6.2 - New | D9: =VLOOKUP($A9,'Vehicle Info'!$A:$W,18,0) -> #N/A | E9: =VLOOKUP($A9,'Vehicle Info'!$A:$W,19,0) -> #N/A | F9: =VLOOKUP($A9,'Vehicle Info'!$A:$W,20,0) -> #N/A | G9: BIKANER | H9: 9,57,358 | I9: 41928 | J9: 4416 | K9: 9,94,869 | L9: 1 | M9: 9574 | N9: - | O9: 9,85,296 | P9: 40 | Q9: 3,94,118 | R9: 13,79,414 | S9: 13403 | T9: 20 | U9: 1,97,059 | V9: 4926 | W9: 11,87,281
A10: AZ1096YJT2A4FA01XJ | B10: Scorpio-N | C10: Z2 D MT 2WD 7 STR - E BS6.2 - New | D10: =VLOOKUP($A10,'Vehicle Info'!$A:$W,18,0) -> #N/A | E10: =VLOOKUP($A10,'Vehicle Info'!$A:$W,19,0) -> #N/A | F10: =VLOOKUP($A10,'Vehicle Info'!$A:$W,20,0) -> #N/A | G10: BIKANER | H10: 9,57,358 | I10: 41928 | J10: 4416 | K10: 9,94,869 | L10: 1 | M10: 9574 | N10: - | O10: 9,85,296 | P10: 40 | Q10: 3,94,118 | R10: 13,79,414 | S10: 13403 | T10: 20 | U10: 1,97,059 | V10: 4926 | W10: 11,87,281
A11: AZ1096YJT2A4FA01SF | B11: Scorpio-N | C11: Z2 D MT 2WD 7 STR - E BS6.2 - New | D11: =VLOOKUP($A11,'Vehicle Info'!$A:$W,18,0) -> #N/A | E11: =VLOOKUP($A11,'Vehicle Info'!$A:$W,19,0) -> #N/A | F11: =VLOOKUP($A11,'Vehicle Info'!$A:$W,20,0) -> #N/A | G11: BIKANER | H11: 9,57,358 | I11: 41928 | J11: 4416 | K11: 9,94,869 | L11: 1 | M11: 9574 | N11: - | O11: 9,85,296 | P11: 40 | Q11: 3,94,118 | R11: 13,79,414 | S11: 13403 | T11: 20 | U11: 1,97,059 | V11: 4926 | W11: 11,87,281

Sheet CSD Index Codes
A1: OEM Model | B1: OEM Variant | C1: CSD Index Code
A2: Bolero | B2: B4 BS6.2 - Refresh | C2: 64361
A3: Bolero | B3: B6 OPT BS6.2 - Refresh | C3: 64829
A4: Marazzo | B4: M2 7 Str BS6.2 | C4: 64921
A5: Marazzo | B5: M4+ 7 Str BS6.2 | C5: 64922
A6: Marazzo | B6: M6+ 7 Str BS6.2 | C6: 64923
A7: PICKUP | B7: BOL CAMPER GOLD ZX 2WD BS6.2 - NEW | C7: 64365-L
A8: Thar | B8: AX OPT D MT 4WD 4S HT BS6.2 | C8: 65288
A9: Thar | B9: LX P AT 4WD 4S HT BS6.2 | C9: 65282
A10: Thar | B10: LXT D AT 4WD 4S HT BS6.2 | C10: 65284
A11: Thar | B11: LXT D MT 2WD 4S HT BS6.2 | C11: 67687
A12: Thar | B12: LXT D MT 4WD 4S HT BS6.2 | C12: 65280
A13: Thar | B13: LXT P AT 2WD 4S HT BS6.2 | C13: 67688
A14: Thar | B14: LXT P MT 4WD 4S HT BS6.2 | C14: 65283
A15: Thar | B15: AXT D MT 2WD 4S HT BS6.2 | C15: 67686
A16: Scorpio-N | B16: Z6 D MT 2WD 7 STR BS6.2 - New | C16: 67352-K
A17: Scorpio-N | B17: Z8 D MT 2WD 7 STR BS6.2 - N | C17: 67353-X
A18: Scorpio-N | B18: Z6 D AT 2WD 7 STR BS6.2 - New | C18: 67684-A
A19: Scorpio-N | B19: Z8 D AT 2WD 7 STR BS6.2 - N | C19: 67685-D
A20: Scorpio-N | B20: Z2 D MT 2WD 7 STR - E BS6.2 - New | C20: 67681
A21: Scorpio-N | B21: Z4 D MT 2WD 7 STR - E BS6.2 - New | C21: 67682
A22: Scorpio-N | B22: Z4 G MT 2WD 7 STR - E BS6.2 - New | C22: 67683
A23: Scorpio-N | B23: Z8 L D AT 2WD 6 STR BS6.2 - N - ADAS | C23: 65292-I
A24: Scorpio-N | B24: Z8 L D AT 2WD 7 STR BS6.2 - N - ADAS | C24: 65293-S
A25: Scorpio-N | B25: Z8 L D AT 2WD 7 STR BS6.2 - N - Black Edition - ADAS | C25: 65294-T
A26: Scorpio-N | B26: Z8 L D AT 4WD 7 STR BS6.2 - N - ADAS | C26: 65295-K
A27: Scorpio-N | B27: Z8 L D AT 4WD 7 STR BS6.2 - N - Black Edition - ADAS | C27: 65296-X
A28: Scorpio-N | B28: Z8 L D MT 2WD 6 STR BS6.2 - N - ADAS | C28: 65297-A
A29: Scorpio-N | B29: Z8 L D MT 2WD 7 STR BS6.2 - N - ADAS | C29: 65298-D
A30: Scorpio-N | B30: Z8 L D MT 2WD 7 STR BS6.2 - N - Black Edition - ADAS | C30: 65299-E
A31: Scorpio-N | B31: Z8 L D MT 4WD 7 STR BS6.2 - N - ADAS | C31: 65300-L
A32: Scorpio-N | B32: Z8 L D MT 4WD 7 STR BS6.2 - N - Black Edition - ADAS | C32: 65301-P
A33: Scorpio-N | B33: Z8 L G AT 2WD 6 STR BS6.2 - N - ADAS | C33: 65302-H
A34: Scorpio-N | B34: Z8 L G AT 2WD 7 STR BS6.2 - N - ADAS | C34: 65303-I
... A67: XUV700 | B67: AX7 PET MT 7 STR BS6.2 - EBONY | C67: 65322-L
A68: XUV400 | B68: EL PRO FC - Battery 39.4 Kwh - Charger 7.2 Kw - E | C68: 67356
A69: XUV400 | B69: EL PRO FC DT - Battery 39.4 Kwh - Charger 7.2 Kw - E | C69: 67357
A70: Bolero Neo | B70: N10 BS6.2 - R - Refresh | C70: 67677
A71: Bolero Neo | B71: N10 OPT BS6.2 - Refresh | C71: 67678
A72: Bolero Neo | B72: N4 BS6.2 - Refresh | C72: 67679
...

Sheet Corporate
A1: OEM Model | B1: OEM Variant | C1: CAT B OEM | D1: CAT B DLR | E1: CAT B TOTAL | F1: BULK 1 (2-5) OEM | G1: BULK 1 (2-5) DLR | H1: BULK 1 (2-5) TOTAL | I1: CAT A OEM | J1: CAT A DLR | K1: CAT A TOTAL | L1: BULK 2 (6-10) OEM | M1: BULK 2 (6-10) DLR | N1: BULK 2 (6-10) TOTAL | O1: CAT F OEM | P1: CAT F DLR | Q1: CAT F TOTAL | R1: BULK 3 (11 & Above) OEM | S1: BULK 3 (11 & Above) DLR | T1: BULK 3 (11 & Above) TOTAL | U1: CAT Y (Premium) OEM | V1: CAT Y (Premium) DLR | W1: CAT Y (Premium) TOTAL | X1: CAT Z (Signature) OEM | Y1: CAT Z (Signature) DLR | Z1: CAT Z (Signature) TOTAL
A2: BE6 | C2: 0 | D2: 0 | E2: =C2+D2 -> 0 | F2: 0 | G2: 0 | H2: =F2+G2 -> 0 | I2: 0 | J2: 0 | K2: =I2+J2 -> 0 | L2: 0 | M2: 0 | N2: =L2+M2 -> 0 | O2: 20000 | P2: 10000 | Q2: =O2+P2 -> 30000 | R2: 20000 | S2: 10000 | T2: =R2+S2 -> 30000 | U2: 20000 | V2: 10000 | W2: =U2+V2 -> 30000 | X2: 20000 | Y2: 10000 | Z2: =X2+Y2 -> 30000
A3: BE6 FE | C3: 0 | D3: 0 | E3: =C3+D3 -> 0 | F3: 0 | G3: 0 | H3: =F3+G3 -> 0 | I3: 0 | J3: 0 | K3: =I3+J3 -> 0 | L3: 0 | M3: 0 | N3: =L3+M3 -> 0 | O3: 20000 | P3: 10000 | Q3: =O3+P3 -> 30000 | R3: 20000 | S3: 10000 | T3: =R3+S3 -> 30000 | U3: 20000 | V3: 10000 | W3: =U3+V3 -> 30000 | X3: 20000 | Y3: 10000 | Z3: =X3+Y3 -> 30000
A4: Bolero | C4: 900 | D4: 900 | E4: =C4+D4 -> 1800 | F4: 900 | G4: 900 | H4: =F4+G4 -> 1800 | I4: 1800 | J4: 900 | K4: =I4+J4 -> 2700 | L4: 1800 | M4: 900 | N4: =L4+M4 -> 2700 | O4: 2200 | P4: 1300 | Q4: =O4+P4 -> 3500 | R4: 2200 | S4: 1300 | T4: =R4+S4 -> 3500 | U4: 2500 | V4: 2500 | W4: =U4+V4 -> 5000 | X4: 18000 | Y4: 12000 | Z4: =X4+Y4 -> 30000
A5: Bolero Neo | C5: 1800 | D5: 900 | E5: =C5+D5 -> 2700 | F5: 1800 | G5: 900 | H5: =F5+G5 -> 2700 | I5: 2200 | J5: 1300 | K5: =I5+J5 -> 3500 | L5: 2200 | M5: 1300 | N5: =L5+M5 -> 3500 | O5: 2700 | P5: 1300 | Q5: =O5+P5 -> 4000 | R5: 2700 | S5: 1300 | T5: =R5+S5 -> 4000 | U5: 2500 | V5: 2500 | W5: =U5+V5 -> 5000 | X5: 18000 | Y5: 12000 | Z5: =X5+Y5 -> 30000
A6: Bolero Neo + | C6: 0 | D6: 0 | E6: =C6+D6 -> 0 | F6: 0 | G6: 0 | H6: =F6+G6 -> 0 | I6: 0 | J6: 0 | K6: =I6+J6 -> 0 | L6: 0 | M6: 0 | N6: =L6+M6 -> 0 | O6: 0 | P6: 0 | Q6: =O6+P6 -> 0 | R6: 0 | S6: 0 | T6: =R6+S6 -> 0 | U6: 2500 | V6: 2500 | W6: =U6+V6 -> 5000 | X6: 24000 | Y6: 16000 | Z6: =X6+Y6 -> 40000
A7: Marazzo | C7: 0 | D7: 0 | E7: =C7+D7 -> 0 | F7: 0 | G7: 0 | H7: =F7+G7 -> 0 | I7: 0 | J7: 0 | K7: =I7+J7 -> 0 | L7: 0 | M7: 0 | N7: =L7+M7 -> 0 | O7: 0 | P7: 0 | Q7: =O7+P7 -> 0 | R7: 0 | S7: 0 | T7: =R7+S7 -> 0 | U7: 2500 | V7: 2500 | W7: =U7+V7 -> 5000 | X7: 24000 | Y7: 16000 | Z7: =X7+Y7 -> 40000
A8: Scorpio | C8: 0 | D8: 0 | E8: =C8+D8 -> 0 | F8: 0 | G8: 0 | H8: =F8+G8 -> 0 | I8: 0 | J8: 0 | K8: =I8+J8 -> 0 | L8: 0 | M8: 0 | N8: =L8+M8 -> 0 | O8: 0 | P8: 0 | Q8: =O8+P8 -> 0 | R8: 0 | S8: 0 | T8: =R8+S8 -> 0 | U8: 2500 | V8: 2500 | W8: =U8+V8 -> 5000 | X8: 24000 | Y8: 16000 | Z8: =X8+Y8 -> 40000
A9: Scorpio-N | C9: 1800 | D9: 1800 | E9: =C9+D9 -> 3600 | F9: 1800 | G9: 1800 | H9: =F9+G9 -> 3600 | I9: 2300 | J9: 2300 | K9: =I9+J9 -> 4600 | L9: 2300 | M9: 2300 | N9: =L9+M9 -> 4600 | O9: 2800 | P9: 2800 | Q9: =O9+P9 -> 5600 | R9: 2800 | S9: 2800 | T9: =R9+S9 -> 5600 | U9: 3750 | V9: 3750 | W9: =U9+V9 -> 7500 | X9: 24000 | Y9: 16000 | Z9: =X9+Y9 -> 40000
A10: Thar | C10: 0 | D10: 0 | E10: =C10+D10 -> 0 | F10: 0 | G10: 0 | H10: =F10+G10 -> 0 | I10: 0 | J10: 0 | K10: =I10+J10 -> 0 | L10: 0 | M10: 0 | N10: =L10+M10 -> 0 | O10: 0 | P10: 0 | Q10: =O10+P10 -> 0 | R10: 0 | S10: 0 | T10: =R10+S10 -> 0 | U10: 2500 | V10: 2500 | W10: =U10+V10 -> 5000 | X10: 18000 | Y10: 12000 | Z10: =X10+Y10 -> 30000
A11: Thar Roxx | C11: 0 | D11: 0 | E11: =C11+D11 -> 0 | F11: 0 | G11: 0 | H11: =F11+G11 -> 0 | I11: 0 | J11: 0 | K11: =I11+J11 -> 0 | L11: 0 | M11: 0 | N11: =L11+M11 -> 0 | O11: 5000 | P11: 5000 | Q11: =O11+P11 -> 10000 | R11: 5000 | S11: 5000 | T11: =R11+S11 -> 10000 | U11: 7500 | V11: 7500 | W11: =U11+V11 -> 15000 | X11: 24000 | Y11: 16000 | Z11: =X11+Y11 -> 40000
A12: XEV9E | C12: 0 | D12: 0 | E12: =C12+D12 -> 0 | F12: 0 | G12: 0 | H12: =F12+G12 -> 0 | I12: 0 | J12: 0 | K12: =I12+J12 -> 0 | L12: 0 | M12: 0 | N12: =L12+M12 -> 0 | O12: 6000 | P12: 4000 | Q12: =O12+P12 -> 10000 | R12: 6000 | S12: 4000 | T12: =R12+S12 -> 10000 | U12: 6000 | V12: 4000 | W12: =U12+V12 -> 10000 | X12: 24000 | Y12: 16000 | Z12: =X12+Y12 -> 40000
A13: XEV9S | C13: 0 | D13: 0 | E13: =C13+D13 -> 0 | F13: 0 | G13: 0 | H13: =F13+G13 -> 0 | I13: 0 | J13: 0 | K13: =I13+J13 -> 0 | L13: 0 | M13: 0 | N13: =L13+M13 -> 0 | O13: 0 | P13: 0 | Q13: =O13+P13 -> 0 | R13: 0 | S13: 0 | T13: =R13+S13 -> 0 | U13: 0 | V13: 0 | W13: =U13+V13 -> 0 | X13: 0 | Y13: 0 | Z13: =X13+Y13 -> 0
... A52: ZOR GRAND RE | C52: 1000 | D52: 500 | E52: =C52+D52 -> 1500 | F52: 1000 | G52: 500 | H52: =F52+G52 -> 1500 | I52: 1200 | J52: 800 | K52: =I52+J52 -> 2000 | L52: 1200 | M52: 800 | N52: =L52+M52 -> 2000 | O52: 1500 | P52: 1000 | Q52: =O52+P52 -> 2500 | R52: 1500 | S52: 1000 | T52: =R52+S52 -> 2500 | U52: 0 | V52: 0 | W52: =U52+V52 -> 0 | X52: 2500 | Y52: 0 | Z52: =X52+Y52 -> 2500

Sheet Exchange
A1: OEM Model | B1: OEM Variant | C1: Exchange Bonus OEM | D1: Exchange Bonus DLR | E1: Exchange Bonus TOTAL | F1: Welcome Bonus OEM | G1: Welcome Bonus DLR | H1: Welcome Bonus TOTAL | I1: Scrap Scheme OEM | J1: Scrap Scheme DLR | K1: Scrap Scheme TOTAL
A2: BE6 | C2: 30000 | D2: 0 | E2: =C2+D2 -> 30000 | H2: =F2+G2 -> 0 | I2: 0 | K2: =I2+J2 -> 0
A3: BE6 FE | C3: 30000 | D3: 0 | E3: =C3+D3 -> 30000 | H3: =F3+G3 -> 0 | I3: 0 | K3: =I3+J3 -> 0
A4: Bolero | C4: 10000 | D4: 0 | E4: =C4+D4 -> 10000 | H4: =F4+G4 -> 0 | I4: 20000 | K4: =I4+J4 -> 20000
A5: Bolero Neo | C5: 10000 | D5: 0 | E5: =C5+D5 -> 10000 | H5: =F5+G5 -> 0 | I5: 20000 | K5: =I5+J5 -> 20000
A6: Bolero Neo + | C6: 10000 | D6: 0 | E6: =C6+D6 -> 10000 | H6: =F6+G6 -> 0 | I6: 20000 | K6: =I6+J6 -> 20000
A7: Marazzo | C7: 15000 | D7: 0 | E7: =C7+D7 -> 15000 | H7: =F7+G7 -> 0 | I7: 35000 | K7: =I7+J7 -> 35000
A8: Scorpio | C8: 20000 | D8: 0 | E8: =C8+D8 -> 20000 | H8: =F8+G8 -> 0 | I8: 20000 | K8: =I8+J8 -> 20000
A9: Scorpio-N | C9: 25000 | D9: 0 | E9: =C9+D9 -> 25000 | H9: =F9+G9 -> 0 | I9: 25000 | K9: =I9+J9 -> 25000
A10: Thar | C10: 0 | D10: 0 | E10: =C10+D10 -> 0 | H10: =F10+G10 -> 0 | I10: 20000 | K10: =I10+J10 -> 20000
A11: Thar Roxx | C11: 0 | D11: 0 | E11: =C11+D11 -> 0 | H11: =F11+G11 -> 0 | I11: 20000 | K11: =I11+J11 -> 20000
A12: XEV9E | C12: 30000 | D12: 0 | E12: =C12+D12 -> 30000 | H12: =F12+G12 -> 0 | I12: 0 | K12: =I12+J12 -> 0
A13: XEV9S | C13: 0 | D13: 0 | E13: =C13+D13 -> 0 | H13: =F13+G13 -> 0 | I13: 0 | K13: =I13+J13 -> 0
... A22: Supro | C22: 45000 | D22: 0 | E22: =C22+D22 -> 45000 | H22: =F22+G22 -> 0 | I22: 45000 | K22: =I22+J22 -> 45000
A23: VEERO | C23: 45000 | D23: 0 | E23: =C23+D23 -> 45000 | F23: 15000 | G23: 0 | H23: =F23+G23 -> 15000 | I23: 45000 | K23: =I23+J23 -> 45000
A24: ALFA LOAD DUO | C24: 4000 | D24: 0 | E24: =C24+D24 -> 4000 | H24: =F24+G24 -> 0 | I24: 0 | K24: =I24+J24 -> 0
A25: ALFA Load Plus | C25: 4000 | D25: 0 | E25: =C25+D25 -> 4000 | H25: =F25+G25 -> 0 | I25: 0 | K25: =I25+J25 -> 0
A26: ALFA Load Plus CNG | C26: 4000 | D26: 0 | E26: =C26+D26 -> 4000 | H26: =F26+G26 -> 0 | I26: 0 | K26: =I26+J26 -> 0
A27: ALFA PASS DUO | C27: 5000 | D27: 0 | E27: =C27+D27 -> 5000 | H27: =F27+G27 -> 0 | I27: 0 | K27: =I27+J27 -> 0
A28: ALFA Passenger CNG | C28: 5000 | D28: 0 | E28: =C28+D28 -> 5000 | H28: =F28+G28 -> 0 | I28: 0 | K28: =I28+J28 -> 0
A29: ALFA Passenger Comfy | C29: 5000 | D29: 0 | E29: =C29+D29 -> 5000 | H29: =F29+G29 -> 0 | I29: 0 | K29: =I29+J29 -> 0
A30: ALFA Passenger Delux | C30: 5000 | D30: 0 | E30: =C30+D30 -> 5000 | H30: =F30+G30 -> 0 | I30: 0 | K30: =I30+J30 -> 0
A31: E ALFA CARGO | C31: 5000 | D31: 0 | E31: =C31+D31 -> 5000 | H31: =F31+G31 -> 0 | I31: 0 | K31: =I31+J31 -> 0
A32: E ALFA PLUS | C32: 5000 | D32: 0 | E32: =C32+D32 -> 5000 | H32: =F32+G32 -> 0 | I32: 0 | K32: =I32+J32 -> 0
A33: E ALFA PLUS HT | C33: 5000 | D33: 0 | E33: =C33+D33 -> 5000 | H33: =F33+G33 -> 0 | I33: 0 | K33: =I33+J33 -> 0
A34: E ALFA SUPER | C34: 5000 | D34: 0 | E34: =C34+D34 -> 5000 | H34: =F34+G34 -> 0 | I34: 0 | K34: =I34+J34 -> 0
A35: JEETO CNG | C35: 5000 | D35: 0 | E35: =C35+D35 -> 5000 | H35: =F35+G35 -> 0 | I35: 0 | K35: =I35+J35 -> 0
... A51: ZOR GRAND RE | C51: 5000 | D51: 0 | E51: =C51+D51 -> 5000 | H51: =F51+G51 -> 0 | I51: 0 | K51: =I51+J51 -> 0

Sheet RSA
A1: Segment | B1: Model | C1: Standard Coverage | D1: Std + 1 Year | E1: Std + 2 Years | F1: Std + 3 Years | G1: Std + 4 Years | H1: Std + 5 Years
A2: BEV | B2: BE6 | C2: 3 Years | D2: 3499 | E2: 4999
A3: BEV | B3: BE6 FE | C3: 3 Years | D3: 3499 | E3: 4999
A4: BEV | B4: XEV9E | C4: 3 Years | D4: 3499 | E4: 4999
A5: BEV | B5: XEV9S | C5: 3 Years | D5: 3499 | E5: 4999
A6: PEROSNAL | B6: SCORPIO-N | C6: 3 Years | D6: 2021 | E6: 3019.62
A7: PEROSNAL | B7: THAR ROXX | C7: 3 Years | D7: 2021 | E7: 3019.62
A8: PERSONAL | B8: XUV400 | C8: 3 Years | D8: 2021 | E8: 3019.62
A9: PEROSNAL | B9: XUV 3XO | C9: 4 Years | D9: 2021
A10: PEROSNAL | B10: XUV3XO EV | C10: NA | D10: NA | E10: NA | F10: NA | G10: NA | H10: NA
A11: PEROSNAL | B11: XUV700 | C11: 3 Years | D11: 2021 | E11: 3019.62
A12: PEROSNAL | B12: XUV7XO | C12: 3 Years | D12: 2021 | E12: 3019.62
A13: PERSONAL | B13: BOLERO | C13: NIL | D13: 2021 | E13: 3020 | F13: 4070
A14: PERSONAL | B14: BOLERO NEO | C14: NIL | D14: 2021 | E14: 3020 | F14: 4070
A15: PERSONAL | B15: BOLERO NEO + | C15: NIL | D15: 2021 | E15: 3020 | F15: 4070
A16: PERSONAL | B16: MARAZZO | C16: NIL | D16: 2021 | E16: 3020 | F16: 4070
A17: PERSONAL | B17: SCORPIO | C17: 2 Years | D17: 2021 | E17: 3020 | F17: 4070
A18: PERSONAL | B18: THAR | C18: 2 Years | D18: 2021 | E18: 3020 | F18: 4070
A19: LMM | B19: ALFA LOAD DUO | C19: NIL | D19: 1307 | E19: 1964 | F19: 2620
A20: LMM | B20: ALFA LOAD PLUS | C20: NIL | D20: 1307 | E20: 1964 | F20: 2620
A21: LMM | B21: ALFA LOAD PLUS CNG | C21: NIL | D21: 1307 | E21: 1964 | F21: 2620
A22: LMM | B22: ALFA PASS DUO | C22: NIL | D22: 1307 | E22: 1964 | F22: 2620
A23: LMM | B23: ALFA PASSENGER CNG | C23: NIL | D23: 1307 | E23: 1964 | F23: 2620
A24: LMM | B24: ALFA PASSENGER COMFY | C24: NIL | D24: 1307 | E24: 1964 | F24: 2620
... A29: LMM | B29: E ALFA SUPER | C29: NIL | D29: 1510 | E29: 2328 | F29: 3147
A30: LMM | B30: JEETO CNG | C30: NIL
A31: LMM | B31: JEETO DIESEL | C31: NIL
A32: LMM | B32: JEETO PETROL | C32: NIL
A33: LMM | B33: JEETO STRONG CNG | C33: NIL
A34: LMM | B34: JEETO STRONG DIESEL | C34: NIL
A35: LMM | B35: TREO AUTO | C35: NIL | D35: 1510 | E35: 2328 | F35: 3147
A36: LMM | B36: TREO PLUS | C36: NIL | D36: 1510 | E36: 2328 | F36: 3147
A37: LMM | B37: TREO PLUS METAL | C37: NIL | D37: 1510 | E37: 2328 | F37: 3147
A38: LMM | B38: TREO METAL | C38: NIL | D38: 1510 | E38: 2328 | F38: 3147
A39: LMM | B39: TREO YAARI | C39: NIL | D39: 1510 | E39: 2328 | F39: 3147
A40: LMM | B40: TREO YAARI CARGO | C40: NIL | D40: 1510 | E40: 2328 | F40: 3147
A41: LMM | B41: TREO ZOR | C41: NIL | D41: 1510 | E41: 2328 | F41: 3147
A42: LMM | B42: UDO | C42: NIL | D42: 1510 | E42: 2328 | F42: 3147 | G42: 4823 | H42: 5970
A43: LMM | B43: ZEO | C43: NIL | D43: 1626 | E43: 2876 | F43: 4266 | G43: 5586 | H43: 6999
A44: LMM | B44: ZOR GRAND | C44: NIL | D44: 1510 | E44: 2328 | F44: 3147
...

Sheet Shield
A1: OEM Model | B1: OEM Variant | C1: Shield Pack | D1: Transmission | E1: Fuel | F1: Standard Warranty | G1: Shield Scheme 1 Name | H1: Shield Scheme 1 Amt | I1: Shield Scheme 2 Name | J1: Shield Scheme 2 Amt
A2: Bolero | F2: 3 Years OR 1 Lakh Kms, Whichever is Earlier | G2: 4th Year OR Up to 1 Lakh kms, Whichever is Earlier | H2: 8999 | I2: 4th & 5th Year OR Up to 1.2 Lakh Kms, Whichever is Earlier | J2: 16999
A3: Bolero Neo | F3: 3 Years OR 1 Lakh Kms, Whichever is Earlier | G3: 4th Year OR Up to 1 Lakh kms, Whichever is Earlier | H3: 9999 | I3: 4th & 5th Year OR Up to 1.2 Lakh Kms, Whichever is Earlier | J3: 18999
A4: Bolero Neo + | F4: 3 Years OR 1 Lakh Kms, Whichever is Earlier | G4: 4th Year OR Up to 1 Lakh kms, Whichever is Earlier | H4: 10999 | I4: 4th & 5th Year OR Up to 1.2 Lakh Kms, Whichever is Earlier | J4: 19999
A5: Marazzo | F5: 3 Years OR 1 Lakh Kms, Whichever is Earlier | G5: 4th Year OR 1.2 Lakh Kms, Whichever is Earlier | H5: 12979 | I5: 4th & 5th Year OR 1.5 Lakh Kms, Whichever is Earlier | J5: 18171
A6: Scorpio | F6: 3 Years OR 1 Lakh Kms, Whichever is Earlier | G6: 4th Year OR Up to 1 Lakh kms, Whichever is Earlier | H6: 17999 | I6: 4th & 5th Year OR Up to 1.2 Lakh Kms, Whichever is Earlier | J6: 32999
A7: Scorpio-N | D7: Manual | E7: Petrol | F7: 3 Years OR 1 Lakh Kms, Whichever is Earlier | G7: 4th Year OR 1.2 Lakh Kms, Whichever is Earlier | H7: 19999 | I7: 4th & 5th Year OR 1.5 Lakh Kms, Whichever is Earlier | J7: 35999
A8: Scorpio-N | D8: Automatic | E8: Petrol | F8: 3 Years OR 1 Lakh Kms, Whichever is Earlier | G8: 4th Year OR 1.2 Lakh Kms, Whichever is Earlier | H8: 23999 | I8: 4th & 5th Year OR 1.5 Lakh Kms, Whichever is Earlier | J8: 41999
A9: Scorpio-N | D9: Manual | E9: Diesel | F9: 3 Years OR 1 Lakh Kms, Whichever is Earlier | G9: 4th Year OR 1.2 Lakh Kms, Whichever is Earlier | H9: 20999 | I9: 4th & 5th Year OR 1.5 Lakh Kms, Whichever is Earlier | J9: 39999
A10: Scorpio-N | D10: Automatic | E10: Diesel | F10: 3 Years OR 1 Lakh Kms, Whichever is Earlier | G10: 4th Year OR 1.2 Lakh Kms, Whichever is Earlier | H10: 24999 | I10: 4th & 5th Year OR 1.5 Lakh Kms, Whichever is Earlier | J10: 49999
A11: Thar | E11: Petrol | F11: 3 Years OR 1 Lakh Kms, Whichever is Earlier | G11: 4th Year OR 1.2 Lakh Kms, Whichever is Earlier | H11: 16999 | I11: 4th & 5th Year OR 1.5 Lakh Kms, Whichever is Earlier | J11: 18999
A12: Thar | E12: Diesel | F12: 3 Years OR 1 Lakh Kms, Whichever is Earlier | G12: 4th Year OR 1.2 Lakh Kms, Whichever is Earlier | H12: 17999 | I12: 4th & 5th Year OR 1.5 Lakh Kms, Whichever is Earlier | J12: 19999
A13: Thar Roxx | D13: Manual | E13: Petrol | F13: 3 Years OR 1 Lakh Kms, Whichever is Earlier | G13: 4th Year OR 1.2 Lakh Kms, Whichever is Earlier | H13: 18999 | I13: 4th & 5th Year OR 1.5 Lakh Kms, Whichever is Earlier | J13: 32999
A14: Thar Roxx | D14: Automatic | E14: Petrol | F14: 3 Years OR 1 Lakh Kms, Whichever is Earlier | G14: 4th Year OR 1.2 Lakh Kms, Whichever is Earlier | H14: 22999 | I14: 4th & 5th Year OR 1.5 Lakh Kms, Whichever is Earlier | J14: 34999
A15: Thar Roxx | D15: Manual | E15: Diesel | F15: 3 Years OR 1 Lakh Kms, Whichever is Earlier | G15: 4th Year OR 1.2 Lakh Kms, Whichever is Earlier | H15: 199999 | I15: 4th & 5th Year OR 1.5 Lakh Kms, Whichever is Earlier | J15: 33999
A16: Thar Roxx | D16: Automatic | E16: Diesel | F16: 3 Years OR 1 Lakh Kms, Whichever is Earlier | G16: 4th Year OR 1.2 Lakh Kms, Whichever is Earlier | H16: 23999 | I16: 4th & 5th Year OR 1.5 Lakh Kms, Whichever is Earlier | J16: 35999
A17: BE6 FE | C17: Pack 2 | F17: 3 Years & Unlimited Kms | G17: 4th Year & Unlimited Kms | H17: 30999 | I17: 4th & 5th Year & Unlimited Kms | J17: 44999
